Workbook

Sheet FORMULARIO
C1: FORMULÁRIO PADRÃO - BANCO D (MODELO DE EXEMPLO)
E4: Empresa avaliadora: | F4: EMPRESA DE AVALIAÇÃO (EXEMPLO)
E5: Junção: | F5: 9999
E6: Nome da junção: | F6: AGÊNCIA DE OUTRO CASO
E7: Protocolo:
E8: Nº do laudo:
E9: Grupo (só consórcio):
E10: Cota (só consórcio):
E11: Proponente:
E12: Endereço (tipo / nome):
E13: Nº:
E14: Complemento:
E15: Bairro:
E16: Cidade:
E17: CEP:
E18: UF:
... E20: Data da visita:
F21: =COUNTA(G22:G33)+COUNTA(M22:M33)
E22: Foi assinalado algum item restritivo?
E23: Área contaminada | I23: Sem infraestrutura básica
E24: Área de preservação ambiental | I24: Mais de uma matrícula
E25: Imóvel encravado | I25: Área embargada
E26: Imóvel tombado | I26: Risco geológico
F33: CNS Cartório | H33: Livro | J33: Nº Matrícula | L33: Dígito
E34: Matrícula do imóvel:
E36: Tipo de operação: | F36: GARANTIA (IMÓVEL URBANO)
E37: Qtde. de vagas de garagem: | M37: Descobertas: | O37: Cobertas:
E38: Possui vagas?
E40: ÁREAS - MATRÍCULA | I40: ESTIMADA
E42: Terreno (m²): | I42: Terreno:
E43: Construída (m²): | I43: Construída:
E44: Comum (m²): | I44: IPTU
E45: Garagem (m²): | I45: Terreno:
E46: Depósito (m²): | I46: Construída:
E47: Total (m²): | F47: =F44+F43 | I47: Áreas sem averbação (m²):
E48: Fração ideal:
E57: Comercialização:
E58: Localização:
E59: Regime de ocupação:
E60: Comentário:
...

Sheet PAG.1
A1: Logo | C1: Laudo de avaliação - Banco D (modelo de exemplo)
A4: Junção: | B4: =+FORMULARIO!F5 | C4: =+FORMULARIO!F6 | F4: Protocolo: | H4: =+FORMULARIO!F7 | J4: Nº laudo: | K4: =+FORMULARIO!F8
A5: =IF(COUNTIF(FORMULARIO!G22:G33,"X")+COUNTIF(FORMULARIO!M22:M33,"X")>0,R5,"") | R5: VIDE CARTA COM PARECER DO BANCO D (conforme normativo interno)
A6: Foto do imóvel | G6: Foto Logradouro
G17: Foto nº imóvel
A23: Grupo: | B23: =+FORMULARIO!F9 | C23: Cota: | D23: =+FORMULARIO!F10
A24: Proponente: | B24: =+FORMULARIO!F11 | J24: Recebimento:
A25: Endereço: | B25: =+FORMULARIO!F12&" "&FORMULARIO!G12 | H25: Nº: | I25: =+FORMULARIO!F13 | J25: =+FORMULARIO!F19
A26: Compl.: | B26: =+FORMULARIO!F14 | D26: Bairro: | E26: =+FORMULARIO!F15 | J26: Data da visita:
A27: Cidade: | B27: =+FORMULARIO!F16 | E27: CEP: | F27: =+FORMULARIO!F17 | H27: UF: | I27: =+FORMULARIO!F18 | J27: =+FORMULARIO!F20
A28: Tipo de operação
A29: =+FORMULARIO!F36
A31: Valor de Liquidez
A32: =+IF(A31="Valor de Mercado",FORMULARIO!J133,FORMULARIO!J135) | E32: (valor por extenso)
C34: CNS Cartório | D34: Livro | E34: Nº Matrícula | F34: Dígito
A35: Matrícula: | C35: =FORMULARIO!F34 | D35: =FORMULARIO!H34 | E35: =FORMULARIO!J34 | F35: =FORMULARIO!L34
A37: Áreas (m²) | G37: Geral
A38: Terreno: | B38: =+FORMULARIO!F42 | G38: Tipo do imóvel: | J38: =FORMULARIO!E106
A39: Construída: | B39: =+FORMULARIO!F43 | G39: Idade aparente: | J39: =FORMULARIO!E114
A40: Comum: | B40: =+FORMULARIO!F44 | G40: Quartos: | J40: =+SUM(FORMULARIO!H118:H119)
A41: Total: | B41: =+FORMULARIO!F47 | G41: Comercialização: | J41: =FORMULARIO!F57
A42: Fração ideal: | B42: =+FORMULARIO!F48 | G42: Ocupação: | J42: =+FORMULARIO!F59
A43: Sem averbação: | B43: =+FORMULARIO!I48 | G43: Uso comercial? | J43: =FORMULARIO!F65
A47: Vagas de garagem
A48: Qtde. de vagas: | C48: =+FORMULARIO!F37
A49: Possui vagas? | C49: =+FORMULARIO!F38
A51: Comentários
A52: =+FORMULARIO!F60
A65: Vistoriador: | B65: =+FORMULARIO!E135 | F65: Data: | G65: =+FORMULARIO!E137
A66: CREA/CAU: | B66: =+FORMULARIO!E136 | F66: Hora: | G66: =+FORMULARIO!E138
A67: Local: | B67: =+FORMULARIO!F64 | H67: Engº.: | I67: =+FORMULARIO!F62
A68: Data do laudo: | B68: =+FORMULARIO!F61 | H68: CREA: | I68: =+FORMULARIO!F63

Sheet PAG.2
A1: Logo | C1: Laudo de avaliação - Banco D (modelo de exemplo)
A6: Características da região
A8: Coleta de lixo: | C8: =+FORMULARIO!F71 | E8: =+FORMULARIO!G71 | G8: =+FORMULARIO!H71
A9: Transporte coletivo: | C9: =+FORMULARIO!F72 | E9: =+FORMULARIO!G72 | G9: =+FORMULARIO!H72
A10: Comércio: | C10: =+FORMULARIO!F73 | E10: =+FORMULARIO!G73 | G10: =+FORMULARIO!H73
A11: Rede bancária: | C11: =+FORMULARIO!F74 | E11: =+FORMULARIO!G74 | G11: =+FORMULARIO!H74
A12: Escola: | C12: =+FORMULARIO!F75 | E12: =+FORMULARIO!G75 | G12: =+FORMULARIO!H75
A13: Saúde: | C13: =+FORMULARIO!F76 | E13: =+FORMULARIO!G76 | G13: =+FORMULARIO!H76
A14: Segurança: | C14: =+FORMULARIO!F77 | E14: =+FORMULARIO!G77 | G14: =+FORMULARIO!H77
A15: Lazer: | C15: =+FORMULARIO!F78 | E15: =+FORMULARIO!G78 | G15: =+FORMULARIO!H78
A18: Terreno e imóvel
A20: =+FORMULARIO!F83 | B20: Água
A21: =+FORMULARIO!F84 | B21: Esgoto sanitário
A22: =+FORMULARIO!F85 | B22: Energia elétrica
A23: =+FORMULARIO!F86 | B23: Telefone
A24: =+FORMULARIO!F87 | B24: Pavimentação
A25: =+FORMULARIO!F88 | B25: Arborização
A26: =+FORMULARIO!F89 | B26: Esgoto pluvial
A27: =+FORMULARIO!F90 | B27: Gás canalizado
A28: =+FORMULARIO!F91 | B28: Iluminação pública
A29: =+FORMULARIO!F92 | B29: Fossa
A30: =+FORMULARIO!F93 | B30: Poço
A35: Descrição do imóvel
A38: Compartimento | E38: Qtde. | F38: Paredes | H38: Pisos | I38: Tetos | K38: Pintura
A39: =+FORMULARIO!E118 | E39: =+FORMULARIO!H118 | F39: =+FORMULARIO!I118 | H39: =+FORMULARIO!J118 | I39: =+FORMULARIO!K118 | K39: =+FORMULARIO!L118
A40: =+FORMULARIO!E119 | E40: =+FORMULARIO!H119 | F40: =+FORMULARIO!I119 | H40: =+FORMULARIO!J119 | I40: =+FORMULARIO!K119 | K40: =+FORMULARIO!L119
A41: =+FORMULARIO!E120 | E41: =+FORMULARIO!H120 | F41: =+FORMULARIO!I120 | H41: =+FORMULARIO!J120 | I41: =+FORMULARIO!K120 | K41: =+FORMULARIO!L120
A42: =+FORMULARIO!E121 | E42: =+FORMULARIO!H121 | F42: =+FORMULARIO!I121 | H42: =+FORMULARIO!J121 | I42: =+FORMULARIO!K121 | K42: =+FORMULARIO!L121
A43: =+FORMULARIO!E122 | E43: =+FORMULARIO!H122 | F43: =+FORMULARIO!I122 | H43: =+FORMULARIO!J122 | I43: =+FORMULARIO!K122 | K43: =+FORMULARIO!L122
A44: =+FORMULARIO!E123 | E44: =+FORMULARIO!H123 | F44: =+FORMULARIO!I123 | H44: =+FORMULARIO!J123 | I44: =+FORMULARIO!K123 | K44: =+FORMULARIO!L123
A45: =+FORMULARIO!E124 | E45: =+FORMULARIO!H124 | F45: =+FORMULARIO!I124 | H45: =+FORMULARIO!J124 | I45: =+FORMULARIO!K124 | K45: =+FORMULARIO!L124
A46: =+FORMULARIO!E125 | E46: =+FORMULARIO!H125 | F46: =+FORMULARIO!I125 | H46: =+FORMULARIO!J125 | I46: =+FORMULARIO!K125 | K46: =+FORMULARIO!L125
A47: =+FORMULARIO!E126 | E47: =+FORMULARIO!H126 | F47: =+FORMULARIO!I126 | H47: =+FORMULARIO!J126 | I47: =+FORMULARIO!K126 | K47: =+FORMULARIO!L126
A48: =+FORMULARIO!E127 | E48: =+FORMULARIO!H127 | F48: =+FORMULARIO!I127 | H48: =+FORMULARIO!J127 | I48: =+FORMULARIO!K127 | K48: =+FORMULARIO!L127
A49: =+FORMULARIO!E128 | E49: =+FORMULARIO!H128 | F49: =+FORMULARIO!I128 | H49: =+FORMULARIO!J128 | I49: =+FORMULARIO!K128 | K49: =+FORMULARIO!L128
A50: =+FORMULARIO!E129 | E50: =+FORMULARIO!H129 | F50: =+FORMULARIO!I129 | H50: =+FORMULARIO!J129 | I50: =+FORMULARIO!K129 | K50: =+FORMULARIO!L129
A51: =+FORMULARIO!E130 | E51: =+FORMULARIO!H130 | F51: =+FORMULARIO!I130 | H51: =+FORMULARIO!J130 | I51: =+FORMULARIO!K130 | K51: =+FORMULARIO!L130
A53: Características do prédio
H55: =FORMULARIO!F155
H56: =FORMULARIO!F156
...

Sheet CROQUI-PLANTA
A1: Logo | C1: Croqui / planta do imóvel
A4: (desenho feito pela equipe)

Sheet FOTOS
A1: Logo | C1: Laudo de avaliação - Banco D (modelo de exemplo)
A4: Junção: | B4: =+PAG.1!B4 | F4: Protocolo: | H4: =+PAG.1!H4 | J4: Nº laudo: | K4: =+PAG.1!K4
A6: RELATÓRIO FOTOGRÁFICO
B9: Inserir as fotos no formato que achar conveniente.
B11: Lembrete:
B12: * fotos de todos os ambientes;
B13: * fotos do logradouro.
